Workbook

Sheet Инструкция
B2: Инструкция по работе с Табелем учета рабочего времени
B4: При возникновении вопросов работы с файлом прошу обращаться к Менеджеру/Специалисту по персоналу вашего Филиала
B6: Файл состоит из 2 Листов, с которыми вы будете работать. 1 Лист - "Шаблон Табеля", он может быть назван по-другому, в нем проводится учет рабочего времени сотрудника на протяжении месяца 2 Лист - "ШР", в него необходимо вставлять значения из Штатного расписания в строку Ниже представлены инструкции по работе с Листами
B10: В 1 Листе - табеле есть несколько ячеек, разделяющихся по категориям доступности для редактирования
G12: Данные ячейки доступны для редактирования, в них вы можете вписывать любые значения, главное, чтобы они были подходили по смыслу и задачи самой ячейки
G14: В данных ячейках вписаны формулы, они находятся под защитой в целях избежания проблем в будущем работы с файлом
G16: В данных ячейках вписаны значения, которые считаются под ними или справа от них, также не доступны для редактирования
B18: В шапке Табеля прописаны все значения, которые считаются, ниже, в случае возникновения вопросов прошу обращаться к Менеджеру/Специалисту по персоналу вашего Филиала
B20: Сам Табель разделен на 3 блока (Синие кнопочки отправят вас на нужное место):
D22: В первом блоке вам необходимо вписать ФИО сотрудника Отдела путем копирования значений из Штатного расписания и отчетный Месяц,
D25: Во втором блоке ведется учет отработанного времени сотрудником, для каждого сотрудника есть 3 строчки для заполнения, у каждой из них есть своя функция, которая должна заполняться в соответствии с задачей: Вид Времени: В данной строке вставляются значения вида времени (Я - явка, Н - Ночное время, ОТ - Отпуск и тд., ниже будет приведен перечень аббревиатур, которые могут быть использованы) Явка: Здесь вписывается количество отработанного времени, которое сотрудник отработал по календарю Ночные часы: Изначально тут стоит формула, которая определяет все ночные смены как 7 отработанных часов, но в исключительных случаях формула может быть удалена и заменена на другое значение
D31: Вид Времени (аббревиатуры):
D32: Я | E32: - | G32: Явка
D33: Д | E33: - | G33: Явка в дневную смену
D34: Н | E34: - | G34: Явка в ночную смену
D35: ОТ | E35: - | G35: Отпуска ежегодн.оплачиваемые или без сохранения ЗП
D36: Х | E36: - | G36: Дни до трудоустройства или после увольнения
D37: Б | E37: - | G37: Оформленный БЛ
D38: ДО | E38: - | G38: Отпуск без сохранения
D39: ПТД | E39: - | G39: Приостановление трудового договора
D40: ОВ | E40: - | G40: Дополнительные выходные дни (оплачиваемые)
D41: Р | E41: - | G41: Беременность и роды
D42: ОЖ | E42: - | G42: Декретный отпуск
D43: РВ | E43: - | G43: Работа в выходной день
D46: Важно!
C47: 1. | D47: Во время выходного дня нельзя ставить "ОТ" (Отпуска ежегодн.оплачиваемые или без сохранения ЗП)
C48: 2. | D48: При ночной смене сотрудника ставится только "Н" (Явка в ночную смену)
D51: В третьем блоке для редактирования вам доступена зона с комментариями, в ней вы можете дать комментарий по каждому сотруднику, в случае необходимости
B54: Во 2 Листе вставляется Штатное расписание вашего Филиала, Отдела
B56: 1. | D56: Изменение Листа со Штатным расписанием производится Менеджером/Специалистом по персоналу, проводится по мере его изменения, добавление новых сотрудников и прочего
B57: 2. | D57: Штатное расписание в строку вы можете найти в ЗУП - Дополнительные отчеты - Штатные сотрудники (АЛ961 изм. АЛ1301)
B58: 3. | D58: Обязательные пункты, которые должны быть у вас в отчете - №, Организация, Подразделение 1, Подразделение 2, Подразделение 3, Подразделение 4, Табельный номер, Сотрудник, Пол, Должность
B59: 4. | D59: Сохраняем Штатное расписание в формате Excel себе на компьютер в удобную для вас папку
B60: 5. | D60: Заходим в сформированный файл
B61: 6. | D61: Выделяем всю таблицу через треугольник в левом верхнем углы таблицы, копируем
B72: 7. | D72: Заходим в данный файл Excel, который сейчас у вас открыт, на лист "ШР"
B73: 8. | D73: Нажимаем также на треугольник в левом верхнем углы таблицы, вставляем
B74: 9. | D74: Готово, файл готов к работе

Sheet пример
B5: № п/п | C5: Месяц: | D5: Апрель | E5: Подразделение 1: | F5: ООО «АЛВИСА», филиал ШАТО АЛВИСА (CHÂTEAU ALVISA) | G5: Подразделение 2: | H5: =IFERROR(INDEX(#REF!,MATCH(пример!$C$9,#REF!,0)),"") | I5: Табель учета рабочего времени | AM5: За первую половину месяца | AU5: За месяц | BC5: Комментарий
C7: ФИО | D7: Табельный номер | E7: Должность | F7: Подразделение 4 | G7: Пол | H7: Вид времени | I7: =VLOOKUP(WEEKDAY(I8,11),'Справочный лист'!$J$3:$K$9,2,FALSE) -> СР | J7: =VLOOKUP(WEEKDAY(J8,11),'Справочный лист'!$J$3:$K$9,2,FALSE) -> ЧТ | K7: =VLOOKUP(WEEKDAY(K8,11),'Справочный лист'!$J$3:$K$9,2,FALSE) -> ПТ | L7: =VLOOKUP(WEEKDAY(L8,11),'Справочный лист'!$J$3:$K$9,2,FALSE) -> СБ | M7: =VLOOKUP(WEEKDAY(M8,11),'Справочный лист'!$J$3:$K$9,2,FALSE) -> ВС | N7: =VLOOKUP(WEEKDAY(N8,11),'Справочный лист'!$J$3:$K$9,2,FALSE) -> ПН | O7: =VLOOKUP(WEEKDAY(O8,11),'Справочный лист'!$J$3:$K$9,2,FALSE) -> ВТ | P7: =VLOOKUP(WEEKDAY(P8,11),'Справочный лист'!$J$3:$K$9,2,FALSE) -> СР | ... AL7: =VLOOKUP(WEEKDAY(AL8,11),'Справочный лист'!$J$3:$K$9,2,FALSE) -> ЧТ | AM7: Отработано | AQ7: Норма часов по ПК | AR7: Среднемесячная норма часов | AS7: Перерабока от нормы часов по ПК | AT7: Переработка от среднемесячной нормы часов | AU7: Отработано | AY7: Норма часов по ПК | AZ7: Среднемесячная норма часов | BA7: Перерабока от нормы часов по ПК | BB7: Переработка от среднемесячной нормы часов
I8: ='Справочный лист'!M3&"."&VLOOKUP($D$5,'Справочный лист'!$M$6:$N$17,2,FALSE)&"."&'Справочный лист'!$M$4 -> 1.4.26 | J8: ='Справочный лист'!N3&"."&VLOOKUP($D$5,'Справочный лист'!$M$6:$N$17,2,FALSE)&"."&'Справочный лист'!$M$4 -> 2.4.26 | K8: ='Справочный лист'!O3&"."&VLOOKUP($D$5,'Справочный лист'!$M$6:$N$17,2,FALSE)&"."&'Справочный лист'!$M$4 -> 3.4.26 | L8: ='Справочный лист'!P3&"."&VLOOKUP($D$5,'Справочный лист'!$M$6:$N$17,2,FALSE)&"."&'Справочный лист'!$M$4 -> 4.4.26 | M8: ='Справочный лист'!Q3&"."&VLOOKUP($D$5,'Справочный лист'!$M$6:$N$17,2,FALSE)&"."&'Справочный лист'!$M$4 -> 5.4.26 | N8: ='Справочный лист'!R3&"."&VLOOKUP($D$5,'Справочный лист'!$M$6:$N$17,2,FALSE)&"."&'Справочный лист'!$M$4 -> 6.4.26 | O8: ='Справочный лист'!S3&"."&VLOOKUP($D$5,'Справочный лист'!$M$6:$N$17,2,FALSE)&"."&'Справочный лист'!$M$4 -> 7.4.26 | P8: ='Справочный лист'!T3&"."&VLOOKUP($D$5,'Справочный лист'!$M$6:$N$17,2,FALSE)&"."&'Справочный лист'!$M$4 -> 8.4.26 | ... AL8: ='Справочный лист'!AP3&"."&VLOOKUP($D$5,'Справочный лист'!$M$6:$N$17,2,FALSE)&"."&'Справочный лист'!$M$4 -> 30.4.26 | AM8: Дни | AN8: Часы | AO8: Дневные часы | AP8: Ночные часы | AU8: Дни | AV8: Часы | AW8: Дневные часы | AX8: Ночные часы
B9: 1 | C9: =[1]ШР!P8 -> Эскеров Аднан Эскерович | D9: ТДЗК-00977 | E9: Руководитель Отдела ЕГАИС | F9: =IFERROR(INDEX([1]ШР!M:M,MATCH('[1]Шаблон Табеля'!C9:C10,[1]ШР!P:P,0)),"") -> Отдел Единой государственной автоматизированной информационной системы | G9: Мужской | H9: Вид времени | I9: Я | J9: Я | K9: Я | N9: Я | O9: Я | P9: Я | Q9: Я | R9: Я | V9: Я | W9: Я | AM9: =IF(C9="","",COUNTIF(I9:W9,"Я")+COUNTIF(I9:W9,"Н")+COUNTIF(I9:W9,"Д")+COUNTIF(I9:W9,"РВ")) -> 10 | AN9: =IF(C9="","",SUM(I10:W10)) -> 80 | AO9: =SUM(I10:W10) -> 80 | AP9: =SUM(I11:W11) -> 0 | AQ9: 80 | AR9: =IF(G9="Женский",'ПК 2 Дагестан'!$G$22/2,'ПК 2 Дагестан'!$F$22/2) -> 80.333333 | AS9: =IFERROR(IF(C9="","",AN9-AQ9),"") -> 0 | AT9: =IF(C9="","",AN9-AR9) -> -0.33333333 | AU9: =IF(C9="","",COUNTIF(I9:AL9,"Я")+COUNTIF(I9:AL9,"Н")+COUNTIF(I9:AL9,"Д")+COUNTIF(I9:AL9,"РВ")) -> 10 | AV9: =SUM(I10:AL11) -> 80 | AW9: =SUM(I10:AL10) -> 80 | AX9: =SUM(I11:AL11) -> 0 | AY9: 159 | AZ9: =IF(G9="Женский",'ПК 2 Дагестан'!$G$22,'ПК 2 Дагестан'!$F$22) -> 160.66667 | BA9: =IFERROR(IF(C9="","",AV9-AY9),"") -> -79 | BB9: =IF(C9="","",AV9-AZ9) -> -80.666667
H10: Явка | I10: 8 | J10: 8 | K10: 8 | N10: 8 | O10: 8 | P10: 8 | Q10: 8 | R10: 8 | V10: 8 | W10: 8
H11: Ночные часы
B12: 2 | C12: =[1]ШР!P9 -> Гасанов Камиль Мурадович | D12: ТДЗК-01621 | E12: Оператор ЕГАИС | F12: =IFERROR(INDEX([1]ШР!M:M,MATCH('[1]Шаблон Табеля'!C12:C13,[1]ШР!P:P,0)),"") -> Отдел Единой государственной автоматизированной информационной системы | G12: Мужской | H12: Вид времени | I12: Я | J12: Я | L12: Я | O12: Я | P12: Я | Q12: Я | R12: Я | S12: Я | T12: Я | V12: Я | W12: Я | AM12: =IF(C12="","",COUNTIF(I12:W12,"Я")+COUNTIF(I12:W12,"Н")+COUNTIF(I12:W12,"Д")+COUNTIF(I12:W12,"РВ")) -> 11 | AN12: =SUM(I13:W14) -> 78 | AO12: =SUM(I13:W13) -> 55 | AP12: =SUM(I14:W14) -> 23 | AQ12: 80 | AR12: =IF(G12="Женский",'ПК 2 Дагестан'!$G$22/2,'ПК 2 Дагестан'!$F$22/2) -> 80.333333 | AS12: =IFERROR(IF(C12="","",AN12-AQ12),"") -> -2 | AT12: =IF(C12="","",AN12-AR12) -> -2.3333333 | AU12: =IF(C12="","",COUNTIF(I12:AL12,"Я")+COUNTIF(I12:AL12,"Н")+COUNTIF(I12:AL12,"Д")+COUNTIF(I12:AL12,"РВ")) -> 11 | AV12: =SUM(I13:AL14) -> 78 | AW12: =SUM(I13:AL13) -> 55 | AX12: =SUM(I14:AL14) -> 23 | AY12: 159 | AZ12: =IF(G12="Женский",'ПК 2 Дагестан'!$G$22,'ПК 2 Дагестан'!$F$22) -> 160.66667 | BA12: =IFERROR(IF(C12="","",AV12-AY12),"") -> -81 | BB12: =IF(C12="","",AV12-AZ12) -> -82.666667
H13: Явка | I13: 2 | J13: 2 | L13: 11 | O13: 8 | P13: 2 | Q13: 2 | R13: 11 | S13: 2 | T13: 2 | V13: 11 | W13: 2
H14: Ночные часы | I14: 2 | J14: 5 | P14: 2 | Q14: 5 | S14: 2 | T14: 5 | W14: 2
B15: 3 | C15: =[1]ШР!P10 -> Герейханов Пирбала Тофикович | D15: ТДЗК-01629 | E15: Оператор ЕГАИС | F15: =IFERROR(INDEX([1]ШР!M:M,MATCH('[1]Шаблон Табеля'!C15:C16,[1]ШР!P:P,0)),"") -> Отдел Единой государственной автоматизированной информационной системы | G15: Мужской | H15: Вид времени | I15: ОТ | J15: ОТ | K15: ОТ | N15: ОТ | O15: ОТ | P15: ОТ | Q15: ОТ | R15: ОТ | V15: ОТ | W15: Я | AM15: =IF(C15="","",COUNTIF(I15:W15,"Я")+COUNTIF(I15:W15,"Н")+COUNTIF(I15:W15,"Д")+COUNTIF(I15:W15,"РВ")) -> 1 | AN15: =SUM(I16:W17) -> 11 | AO15: =SUM(I16:W16) -> 11 | AP15: =SUM(I17:W17) -> 0 | AQ15: 80 | AR15: =IF(G15="Женский",'ПК 2 Дагестан'!$G$22/2,'ПК 2 Дагестан'!$F$22/2) -> 80.333333 | AS15: =IFERROR(IF(C15="","",AN15-AQ15),"") -> -69 | AT15: =IF(C15="","",AN15-AR15) -> -69.333333 | AU15: =IF(C15="","",COUNTIF(I15:AL15,"Я")+COUNTIF(I15:AL15,"Н")+COUNTIF(I15:AL15,"Д")+COUNTIF(I15:AL15,"РВ")) -> 1 | AV15: =SUM(I16:AL17) -> 11 | AW15: =SUM(I16:AL16) -> 11 | AX15: =SUM(I17:AL17) -> 0 | AY15: 159 | AZ15: =IF(G15="Женский",'ПК 2 Дагестан'!$G$22,'ПК 2 Дагестан'!$F$22) -> 160.66667 | BA15: =IFERROR(IF(C15="","",AV15-AY15),"") -> -148 | BB15: =IF(C15="","",AV15-AZ15) -> -149.66667
H16: Явка | W16: 11
H17: Ночные часы
B18: 4 | C18: =[1]ШР!P11 -> Гусейнов Вели Гусеевич | D18: ТДЗК-01998 | E18: Оператор ЕГАИС | F18: =IFERROR(INDEX([1]ШР!M:M,MATCH('[1]Шаблон Табеля'!C18:C19,[1]ШР!P:P,0)),"") -> Отдел Единой государственной автоматизированной информационной системы | G18: Мужской | H18: Вид времени | J18: Я | K18: Я | L18: Я | M18: Я | O18: Я | P18: Я | Q18: Я | R18: Я | V18: Я | W18: Я | AM18: =IF(C18="","",COUNTIF(I18:W18,"Я")+COUNTIF(I18:W18,"Н")+COUNTIF(I18:W18,"Д")+COUNTIF(I18:W18,"РВ")) -> 10 | AN18: =SUM(I19:W20) -> 82 | AO18: =SUM(I19:W19) -> 61 | AP18: =SUM(I20:W20) -> 21 | AQ18: 80 | AR18: =IF(G18="Женский",'ПК 2 Дагестан'!$G$22/2,'ПК 2 Дагестан'!$F$22/2) -> 80.333333 | AS18: =IFERROR(IF(C18="","",AN18-AQ18),"") -> 2 | AT18: =IF(C18="","",AN18-AR18) -> 1.6666667 | AU18: =IF(C18="","",COUNTIF(I18:AL18,"Я")+COUNTIF(I18:AL18,"Н")+COUNTIF(I18:AL18,"Д")+COUNTIF(I18:AL18,"РВ")) -> 10 | AV18: =SUM(I19:AL20) -> 82 | AW18: =SUM(I19:AL19) -> 61 | AX18: =SUM(I20:AL20) -> 21 | AY18: 159 | AZ18: =IF(G18="Женский",'ПК 2 Дагестан'!$G$22,'ПК 2 Дагестан'!$F$22) -> 160.66667 | BA18: =IFERROR(IF(C18="","",AV18-AY18),"") -> -77 | BB18: =IF(C18="","",AV18-AZ18) -> -78.666667
H19: Явка | J19: 11 | K19: 2 | L19: 4 | M19: 2 | O19: 8 | P19: 11 | Q19: 2 | R19: 2 | V19: 11 | W19: 8
H20: Ночные часы | K20: 2 | L20: 7 | M20: 5 | Q20: 2 | R20: 5
B21: 5 | C21: =[1]ШР!P12 -> Мирзоев Ханахмед Бегахмедович | D21: ТДЗК-01742 | E21: Ст.Оператор ЕГАИС | F21: =IFERROR(INDEX([1]ШР!M:M,MATCH('[1]Шаблон Табеля'!C21:C22,[1]ШР!P:P,0)),"") -> Отдел Единой государственной автоматизированной информационной системы | G21: Мужской | H21: Вид времени | I21: Я | K21: Я | L21: Я | M21: Я | O21: Я | P21: Я | Q21: Я | R21: Я | S21: Я | V21: Я | W21: Я | AM21: =IF(C21="","",COUNTIF(I21:W21,"Я")+COUNTIF(I21:W21,"Н")+COUNTIF(I21:W21,"Д")+COUNTIF(I21:W21,"РВ")) -> 11 | AN21: =SUM(I22:W23) -> 88 | AO21: =SUM(I22:W22) -> 67 | AP21: =SUM(I23:W23) -> 21 | AQ21: 80 | AR21: =IF(G21="Женский",'ПК 2 Дагестан'!$G$22/2,'ПК 2 Дагестан'!$F$22/2) -> 80.333333 | AS21: =IFERROR(IF(C21="","",AN21-AQ21),"") -> 8 | AT21: =IF(C21="","",AN21-AR21) -> 7.6666667 | AU21: =IF(C21="","",COUNTIF(I21:AL21,"Я")+COUNTIF(I21:AL21,"Н")+COUNTIF(I21:AL21,"Д")+COUNTIF(I21:AL21,"РВ")) -> 11 | AV21: =SUM(I22:AL23) -> 88 | AW21: =SUM(I22:AL22) -> 67 | AX21: =SUM(I23:AL23) -> 21 | AY21: 159 | AZ21: =IF(G21="Женский",'ПК 2 Дагестан'!$G$22,'ПК 2 Дагестан'!$F$22) -> 160.66667 | BA21: =IFERROR(IF(C21="","",AV21-AY21),"") -> -71 | BB21: =IF(C21="","",AV21-AZ21) -> -72.666667
H22: Явка | I22: 11 | K22: 11 | L22: 2 | M22: 2 | O22: 11 | P22: 11 | Q22: 11 | R22: 2 | S22: 2 | V22: 2 | W22: 2
H23: Ночные часы | L23: 2 | M23: 5 | R23: 2 | S23: 5 | V23: 2 | W23: 5

Sheet Лист1
A2: Штатные сотрудники
A4: Отбор:
A6: № | B6: Организация | C6: Подразделение1 | E6: Подразделение2 | F6: Подразделение3 | G6: Подразделение4 | H6: Подразделение5 | I6: Табельный номер | J6: Сотрудник | K6: Должность | L6: Функция ШР | M6: Тарифная сетка | N6: Дата приема | O6: Состояние
A8: 3 | B8: АЛВИСА ООО | C8: ООО «АЛВИСА», филиал ШАТО АЛВИСА (CHÂTEAU ALVISA) | E8: Техническая служба | F8: Отдел главного механика | G8: Группа обслуживания вторичного виноделия | I8: ТДЗК-00916 | J8: Аликберов Рамазан Магомедович | K8: Электрогазосварщик | L8: Обслуживающее производство 25 | M8: Рабочие, занятые на объектах повышенной опасности | N8: 08.02.2023 | O8: Работа
A9: 4 | B9: АЛВИСА ООО | C9: ООО «АЛВИСА», филиал ШАТО АЛВИСА (CHÂTEAU ALVISA) | E9: Техническая служба | F9: Отдел главного механика | G9: Группа обслуживания вторичного виноделия | I9: ТДЗК-02551 | J9: Альдеров Исрафил Баласиевич | K9: Наладчик оборудования в производстве пищевой продукции | L9: Обслуживающее производство 25 | M9: Рабочие, занятые на обслуживании КИПиА и оборудования | N9: 23.09.2025 | O9: Работа
A10: 5 | B10: АЛВИСА ООО | C10: ООО «АЛВИСА», филиал ШАТО АЛВИСА (CHÂTEAU ALVISA) | E10: Техническая служба | F10: Отдел главного механика | G10: Группа обслуживания вторичного виноделия | I10: ТДЗК-00744 | J10: Беньяминов Геннадий Олегович | K10: Наладчик оборудования в производстве пищевой продукции | L10: Обслуживающее производство 25 | M10: Рабочие, занятые на обслуживании КИПиА и оборудования | N10: 05.10.2022 | O10: Работа
A11: 6 | B11: АЛВИСА ООО | C11: ООО «АЛВИСА», филиал ШАТО АЛВИСА (CHÂTEAU ALVISA) | E11: Техническая служба | F11: Отдел главного механика | G11: Группа обслуживания вторичного виноделия | I11: ТДЗК-01942 | J11: Гусейнов Тигран Вагидович | K11: Наладчик оборудования в производстве пищевой продукции | L11: Обслуживающее производство 25 | M11: Рабочие, занятые на обслуживании КИПиА и оборудования | N11: 25.11.2024 | O11: Работа
A12: 7 | B12: АЛВИСА ООО | C12: ООО «АЛВИСА», филиал ШАТО АЛВИСА (CHÂTEAU ALVISA) | E12: Техническая служба | F12: Отдел главного механика | G12: Группа обслуживания вторичного виноделия | I12: ТДЗК-02543 | J12: Попов Алексей Александрович | K12: Наладчик оборудования в производстве пищевой продукции | L12: Обслуживающее производство 25 | M12: Рабочие, занятые на обслуживании КИПиА и оборудования | N12: 16.09.2025 | O12: Работа
A13: 8 | B13: АЛВИСА ООО | C13: ООО «АЛВИСА», филиал ШАТО АЛВИСА (CHÂTEAU ALVISA) | E13: Техническая служба | F13: Отдел главного механика | G13: Группа обслуживания вторичного виноделия | I13: ТДЗК-01374 | J13: Рагимов Муслим Керимович | K13: Наладчик оборудования в производстве пищевой продукции | L13: Обслуживающее производство 25 | M13: Рабочие, занятые на обслуживании КИПиА и оборудования | N13: 18.10.2023 | O13: Работа
A14: 9 | B14: АЛВИСА ООО | C14: ООО «АЛВИСА», филиал ШАТО АЛВИСА (CHÂTEAU ALVISA) | E14: Техническая служба | F14: Отдел главного механика | G14: Группа обслуживания вторичного виноделия | I14: ТДЗК-02166 | J14: Умаров Осман Богавутдинович | K14: Наладчик оборудования в производстве пищевой продукции | L14: Обслуживающее производство 25 | M14: Рабочие, занятые на обслуживании КИПиА и оборудования | N14: 16.04.2025 | O14: Работа
A15: 10 | B15: АЛВИСА ООО | C15: ООО «АЛВИСА», филиал ШАТО АЛВИСА (CHÂTEAU ALVISA) | E15: Техническая служба | F15: Отдел главного механика | G15: Группа обслуживания вторичного виноделия | I15: ТДЗК-02459 | J15: Быков Артем Юрьевич | K15: Главный механик | L15: Обслуживающее производство 25 | N15: 18.08.2025 | O15: Работа
A16: 11 | B16: АЛВИСА ООО | C16: ООО «АЛВИСА», филиал ШАТО АЛВИСА (CHÂTEAU ALVISA) | E16: Техническая служба | F16: Отдел главного механика | G16: Группа обслуживания вторичного виноделия | I16: ТДЗК-02230 | J16: Майоров Андрей Борисович | K16: Техник по наладке и испытаниям | L16: Обслуживающее производство 25 | N16: 26.05.2025 | O16: Работа
A17: 12 | B17: АЛВИСА ООО | C17: ООО «АЛВИСА», филиал ШАТО АЛВИСА (CHÂTEAU ALVISA) | E17: Техническая служба | F17: Отдел главного механика | G17: Группа обслуживания первичного виноделия | I17: ТДЗК-02204 | J17: Махмудов Курбан Сафигулахович | K17: Электрогазосварщик | L17: Обслуживающее производство 25 | M17: Рабочие, занятые на объектах повышенной опасности | N17: 12.05.2025 | O17: Работа
A18: 13 | B18: АЛВИСА ООО | C18: ООО «АЛВИСА», филиал ШАТО АЛВИСА (CHÂTEAU ALVISA) | E18: Техническая служба | F18: Отдел главного механика | G18: Группа обслуживания первичного виноделия | I18: ТДЗК-01790 | J18: Гасайниев Мурад Рабаданович | K18: Наладчик оборудования в производстве пищевой продукции | L18: Обслуживающее производство 25 | M18: Рабочие, занятые на обслуживании КИПиА и оборудования | N18: 26.08.2024 | O18: Работа
A19: 14 | B19: АЛВИСА ООО | C19: ООО «АЛВИСА», филиал ШАТО АЛВИСА (CHÂTEAU ALVISA) | E19: Техническая служба | F19: Отдел главного механика | G19: Группа обслуживания первичного виноделия | I19: ТДЗК-02297 | J19: Марданов Багир Юрьевич | K19: Наладчик оборудования в производстве пищевой продукции | L19: Обслуживающее производство 25 | M19: Рабочие, занятые на обслуживании КИПиА и оборудования | N19: 20.06.2025 | O19: Работа
A20: 15 | B20: АЛВИСА ООО | C20: ООО «АЛВИСА», филиал ШАТО АЛВИСА (CHÂTEAU ALVISA) | E20: Техническая служба | F20: Отдел главного механика | G20: Группа контрактного производства | I20: ТДЗК-02526 | J20: Притчин Сергей Александрович | K20: Ведущий инженер-механик | L20: Обслуживающее производство 25 | N20: 08.09.2025 | O20: Работа
A21: 16 | B21: АЛВИСА ООО | C21: ООО «АЛВИСА», филиал ШАТО АЛВИСА (CHÂTEAU ALVISA) | E21: Техническая служба | F21: Отдел главного энергетика | I21: ТДЗК-01984 | J21: Шевцов Василий Евгеньевич | K21: Главный энергетик | L21: Обслуживающее производство 25 | N21: 13.01.2025 | O21: Работа
A22: 17 | B22: АЛВИСА ООО | C22: ООО «АЛВИСА», филиал ШАТО АЛВИСА (CHÂTEAU ALVISA) | E22: Техническая служба | F22: Отдел главного энергетика | I22: ТДЗК-02205 | J22: Абдурахманов Фазаил Субетович | K22: Электромонтер по ремонту и наладке электрооборудования | L22: Обслуживающее производство 25 | M22: Рабочие, занятые на обслуживании электрооборудования | N22: 12.05.2025 | O22: Работа
A23: 18 | B23: АЛВИСА ООО | C23: ООО «АЛВИСА», филиал ШАТО АЛВИСА (CHÂTEAU ALVISA) | E23: Техническая служба | F23: Отдел главного энергетика | I23: ТДЗК-01397 | J23: Агаев Агай Гаджимурадович | K23: Электромонтер по ремонту и наладке электрооборудования | L23: Обслуживающее производство 25 | M23: Рабочие, занятые на обслуживании электрооборудования | N23: 01.11.2023 | O23: Работа
A24: 19 | B24: АЛВИСА ООО | C24: ООО «АЛВИСА», филиал ШАТО АЛВИСА (CHÂTEAU ALVISA) | E24: Техническая служба | F24: Отдел главного энергетика | I24: ТДЗК-01690 | J24: Бондарев Владислав Юрьевич | K24: Электромонтер по ремонту и наладке электрооборудования | L24: Обслуживающее производство 25 | M24: Рабочие, занятые на обслуживании электрооборудования | N24: 24.06.2024 | O24: Работа
A25: 20 | B25: АЛВИСА ООО | C25: ООО «АЛВИСА», филиал ШАТО АЛВИСА (CHÂTEAU ALVISA) | E25: Техническая служба | F25: Отдел главного энергетика | I25: ТДЗК-02395 | J25: Дадашев Видади Миллетович | K25: Электромонтер по ремонту и наладке электрооборудования | L25: Обслуживающее производство 25 | M25: Рабочие, занятые на обслуживании электрооборудования | N25: 01.08.2025 | O25: Работа
A26: 21 | B26: АЛВИСА ООО | C26: ООО «АЛВИСА», филиал ШАТО АЛВИСА (CHÂTEAU ALVISA) | E26: Техническая служба | F26: Отдел главного энергетика | I26: ТДЗК-01888 | J26: Селимов Рустам Абдулвагабович | K26: Электромонтер по ремонту и наладке электрооборудования | L26: Обслуживающее производство 25 | M26: Рабочие, занятые на обслуживании электрооборудования | N26: 21.10.2024 | O26: Работа
A27: 22 | B27: АЛВИСА ООО | C27: ООО «АЛВИСА», филиал ШАТО АЛВИСА (CHÂTEAU ALVISA) | E27: Техническая служба | F27: Отдел главного энергетика | G27: Энергетический блок | I27: ТДЗК-01420 | J27: Генжалиев Фаик Сафаралиевич | K27: Оператор энергоблока | L27: Обслуживающее производство 25 | M27: Рабочие, занятые на объектах повышенной опасности | N27: 29.11.2023 | O27: Работа
A28: 23 | B28: АЛВИСА ООО | C28: ООО «АЛВИСА», филиал ШАТО АЛВИСА (CHÂTEAU ALVISA) | E28: Техническая служба | F28: Отдел главного энергетика | G28: Энергетический блок | I28: ТДЗК-00838 | J28: Гусейнов Ариф Садыкович | K28: Оператор энергоблока | L28: Обслуживающее производство 25 | M28: Рабочие, занятые на объектах повышенной опасности | N28: 12.12.2022 | O28: Работа
A29: 24 | B29: АЛВИСА ООО | C29: ООО «АЛВИСА», филиал ШАТО АЛВИСА (CHÂTEAU ALVISA) | E29: Техническая служба | F29: Отдел главного энергетика | G29: Энергетический блок | I29: ТДЗК-00746 | J29: Гусейнов Нариман Садыкович | K29: Оператор энергоблока | L29: Обслуживающее производство 25 | M29: Рабочие, занятые на объектах повышенной опасности | N29: 06.10.2022 | O29: Работа
A30: 25 | B30: АЛВИСА ООО | C30: ООО «АЛВИСА», филиал ШАТО АЛВИСА (CHÂTEAU ALVISA) | E30: Техническая служба | F30: Отдел главного энергетика | G30: Энергетический блок | I30: ТДЗК-01971 | J30: Дадашев Насрулла Черкезович | K30: Оператор энергоблока | L30: Обслуживающее производство 25 | M30: Рабочие, занятые на объектах повышенной опасности | N30: 19.12.2024 | O30: Работа
A31: 26 | B31: АЛВИСА ООО | C31: ООО «АЛВИСА», филиал ШАТО АЛВИСА (CHÂTEAU ALVISA) | E31: Техническая служба | F31: Отдел главного энергетика | G31: Группа контрольно-измерительных приборов и аппаратуры | I31: ТДЗК-02580 | J31: Асланов Расул Зейнутдинович | K31: Слесарь контрольно-измерительных приборов и аппаратуры | L31: Обслуживающее производство 25 | N31: 06.10.2025 | O31: Работа
A32: 27 | B32: АЛВИСА ООО | C32: ООО «АЛВИСА», филиал ШАТО АЛВИСА (CHÂTEAU ALVISA) | E32: Техническая служба | F32: Отдел главного энергетика | G32: Группа контрольно-измерительных приборов и аппаратуры | I32: ТДЗК-01330 | J32: Кадиев Нариман Хасбулаевич | K32: Инженер по контрольно-измерительным приборам и автоматике | L32: Обслуживающее производство 25 | N32: 25.09.2023 | O32: Работа
A33: 28 | B33: АЛВИСА ООО | C33: ООО «АЛВИСА», филиал ШАТО АЛВИСА (CHÂTEAU ALVISA) | E33: Техническая служба | F33: Отдел главного энергетика | G33: Группа контрольно-измерительных приборов и аппаратуры | I33: ТДЗК-02364 | J33: Казаков Сергей Викторович | K33: Инженер по контрольно-измерительным приборам и автоматике | L33: Обслуживающее производство 25 | N33: 16.07.2025 | O33: Работа
A34: 29 | B34: АЛВИСА ООО | C34: ООО «АЛВИСА», филиал ШАТО АЛВИСА (CHÂTEAU ALVISA) | E34: Техническая служба | F34: Отдел главного энергетика | G34: Группа контрольно-измерительных приборов и аппаратуры | I34: ТДЗК-01769 | J34: Касумбеков Аманат Османбекович | K34: Инженер по контрольно-измерительным приборам и автоматике | L34: Обслуживающее производство 25 | N34: 13.08.2024 | O34: Болезнь
A35: 30 | B35: АЛВИСА ООО | C35: ООО «АЛВИСА», филиал ШАТО АЛВИСА (CHÂTEAU ALVISA) | E35: Техническая служба | F35: Отдел главного энергетика | G35: Группа контрольно-измерительных приборов и аппаратуры | I35: ТДЗК-01506 | J35: Шинкоренко Сергей Васильевич | K35: Инженер по контрольно-измерительным приборам и автоматике | L35: Обслуживающее производство 25 | N35: 28.02.2024 | O35: Работа
A36: 31 | B36: АЛВИСА ООО | C36: ООО «АЛВИСА», филиал ШАТО АЛВИСА (CHÂTEAU ALVISA) | E36: Техническая служба | F36: Отдел главного энергетика | G36: Группа контрольно-измерительных приборов и аппаратуры | I36: ТДЗК-02408 | J36: Шлеенкин Дмитрий Александрович | K36: Руководитель группы контрольно-измерительных приборов и аппаратуры | L36: Обслуживающее производство 25 | N36: 04.08.2025 | O36: Работа
A37: 32 | B37: АЛВИСА ООО | C37: ООО «АЛВИСА», филиал ШАТО АЛВИСА (CHÂTEAU ALVISA) | E37: Техническая служба | F37: Отдел главного энергетика | G37: Группа контрольно-измерительных приборов и аппаратуры | H37: Группа контрактного производства | I37: ТДЗК-02098 | J37: Джабраилов Нияметдин Ифритдинович | K37: Инженер по контрольно-измерительным приборам и автоматике | L37: Обслуживающее производство 25 | N37: 06.03.2025 | O37: Работа
A38: 33 | B38: АЛВИСА ООО | C38: ООО «АЛВИСА», филиал ШАТО АЛВИСА (CHÂTEAU ALVISA) | E38: Техническая служба | F38: Отдел главного энергетика | G38: Группа контрольно-измерительных приборов и аппаратуры | H38: Группа контрактного производства | I38: ТДЗК-02609 | J38: Тучин Дмитрий Павлович | K38: Инженер по контрольно-измерительным приборам и автоматике | L38: Обслуживающее производство 25 | N38: 05.11.2025 | O38: Работа
A39: 34 | B39: АЛВИСА ООО | C39: ООО «АЛВИСА», филиал ШАТО АЛВИСА (CHÂTEAU ALVISA) | E39: Техническая служба | F39: Очистные сооружения | I39: ТДЗК-01923 | J39: Гасанов Руслан Гасанович | K39: Оператор очистных сооружений | L39: Обслуживающее производство 25 | M39: Рабочие, занятые на объектах повышенной опасности | N39: 11.11.2024 | O39: Работа
A40: 35 | B40: АЛВИСА ООО | C40: ООО «АЛВИСА», филиал ШАТО АЛВИСА (CHÂTEAU ALVISA) | E40: Техническая служба | F40: Очистные сооружения | I40: ТДЗК-01893 | J40: Магомедов Заур Бабекович | K40: Оператор очистных сооружений | L40: Обслуживающее производство 25 | M40: Рабочие, занятые на объектах повышенной опасности | N40: 21.10.2024 | O40: Работа
A41: 36 | B41: АЛВИСА ООО | C41: ООО «АЛВИСА», филиал ШАТО АЛВИСА (CHÂTEAU ALVISA) | E41: Техническая служба | F41: Очистные сооружения | I41: ТДЗК-01891 | J41: Магомедов Расим Бабекович | K41: Оператор очистных сооружений | L41: Обслуживающее производство 25 | M41: Рабочие, занятые на объектах повышенной опасности | N41: 21.10.2024 | O41: Работа
A42: 37 | B42: АЛВИСА ООО | C42: ООО «АЛВИСА», филиал ШАТО АЛВИСА (CHÂTEAU ALVISA) | E42: Техническая служба | F42: Очистные сооружения | I42: ТДЗК-02328 | J42: Сурхаев Джабраил Магомедович | K42: Оператор очистных сооружений | L42: Обслуживающее производство 25 | M42: Рабочие, занятые на объектах повышенной опасности | N42: 01.07.2025 | O42: Работа
A43: 38 | B43: АЛВИСА ООО | C43: ООО «АЛВИСА», филиал ШАТО АЛВИСА (CHÂTEAU ALVISA) | E43: Техническая служба | F43: Очистные сооружения | I43: ТДЗК-00098 | J43: Рамазанов Ринат Вагифович | K43: Руководитель очистных сооружений | L43: Обслуживающее производство 25 | N43: 29.07.2022 | O43: Работа
A44: 39 | B44: АЛВИСА ООО | C44: ООО «АЛВИСА», филиал ШАТО АЛВИСА (CHÂTEAU ALVISA) | E44: Техническая служба | F44: Очистные сооружения | I44: ТДЗК-02510 | J44: Нурмагомедова Фатимат Турачевна | K44: Лаборант-пробоотборщик | L44: Обслуживающее производство 25 | N44: 01.09.2025 | O44: Работа
...

Sheet ПК 1
AI2: За полный месяц | AN2: За первую половину месяца
C3: Месяц | D3: Часов за день ("Явка") | AI3: По графику | AK3: По производств. календарю | AN3: По графику
AK4: рабочих | AM4: не- раб. дней
D5: 1 | E5: 2 | F5: 3 | G5: 4 | H5: 5 | I5: 6 | J5: 7 | K5: 8 | L5: 9 | M5: 10 | N5: 11 | O5: 12 | P5: 13 | Q5: 14 | R5: 15 | S5: 16 | T5: 17 | U5: 18 | V5: 19 | W5: 20 | X5: 21 | Y5: 22 | Z5: 23 | AA5: 24 | AB5: 25 | AC5: 26 | AD5: 27 | AE5: 28 | AF5: 29 | AG5: 30 | AH5: 31 | AI5: дней | AJ5: часов | AK5: дней | AL5: часов | AN5: дней | AO5: часов
C6: Январь | O6: 8 | P6: 8 | Q6: 8 | R6: 8 | S6: 8 | V6: 8 | W6: 8 | X6: 8 | Y6: 8 | Z6: 8 | AC6: 8 | AD6: 8 | AE6: 8 | AF6: 8 | AG6: 8 | AI6: 17 | AJ6: 136 | AK6: 17 | AL6: 136 | AM6: 14 | AN6: =COUNT(D6:R6) -> 4 | AO6: =SUM(D6:R6) -> 32
C7: Февраль | E7: 8 | F7: 8 | G7: 8 | H7: 8 | I7: 8 | L7: 8 | M7: 8 | N7: 8 | O7: 8 | P7: 8 | S7: 8 | T7: 8 | U7: 8 | V7: 8 | W7: 8 | AA7: 8 | AB7: 8 | AC7: 8 | AD7: 8 | AF7: Х | AG7: Х | AH7: Х | AI7: 20 | AJ7: 160 | AK7: 20 | AL7: 160 | AM7: 8 | AN7: =COUNT(D7:R7) -> 10 | AO7: =SUM(D7:R7) -> 80
C8: Март | E8: 8 | F8: 8 | G8: 8 | H8: 8 | I8: 8 | M8: 8 | N8: 8 | O8: 8 | P8: 8 | S8: 8 | T8: 8 | U8: 8 | V8: 7 | Z8: 8 | AA8: 8 | AB8: 8 | AC8: 8 | AD8: 8 | AG8: 8 | AH8: 8 | AI8: 21 | AJ8: 167 | AK8: 21 | AL8: 167 | AM8: 10 | AN8: =COUNT(D8:R8) -> 9 | AO8: =SUM(D8:R8) -> 72
C9: 1 квартал | AI9: 58 | AJ9: 463 | AK9: 58 | AL9: 463 | AM9: 32 | AN9: =SUM(AN6:AN8) -> 23 | AO9: =SUM(AO6:AO8) -> 184
C10: Апрель | D10: 8 | E10: 8 | F10: 8 | I10: 8 | J10: 8 | K10: 8 | L10: 8 | M10: 8 | P10: 8 | Q10: 8 | R10: 8 | S10: 8 | T10: 8 | W10: 8 | X10: 8 | Y10: 8 | Z10: 8 | AA10: 8 | AD10: 8 | AE10: 7 | AG10: 7 | AH10: Х | AI10: 21 | AJ10: 166 | AK10: 21 | AL10: 166 | AM10: 9 | AN10: =COUNT(D10:R10) -> 11 | AO10: =SUM(D10:R10) -> 88
C11: Май | G11: 8 | H11: 8 | I11: 8 | J11: 8 | K11: 7 | O11: 8 | P11: 8 | Q11: 8 | R11: 8 | U11: 8 | V11: 8 | W11: 8 | X11: 8 | Y11: 8 | AB11: 8 | AC11: 7 | AE11: 8 | AF11: 8 | AI11: 18 | AJ11: 144 | AK11: 18 | AL11: 144 | AM11: 13 | AN11: =COUNT(D11:R11) -> 9 | AO11: =SUM(D11:R11) -> 71
C12: Июнь | D12: 8 | E12: 8 | F12: 8 | G12: 8 | H12: 8 | K12: 8 | L12: 8 | M12: 8 | N12: 7 | R12: 8 | S12: 8 | T12: 8 | U12: 8 | V12: 8 | Y12: 8 | Z12: 8 | AA12: 8 | AB12: 8 | AC12: 8 | AF12: 8 | AG12: 8 | AH12: Х | AI12: 19 | AJ12: 151 | AK12: 19 | AL12: 151 | AM12: 11 | AN12: =COUNT(D12:R12) -> 10 | AO12: =SUM(D12:R12) -> 79
C13: 2 квартал | AI13: 58 | AJ13: 461 | AK13: 58 | AL13: 461 | AM13: 33 | AN13: =SUM(AN10:AN12) -> 30 | AO13: =SUM(AO10:AO12) -> 238
C14: Июль | D14: 8 | E14: 8 | F14: 8 | I14: 8 | J14: 8 | K14: 8 | L14: 8 | M14: 8 | P14: 8 | Q14: 8 | R14: 8 | S14: 8 | T14: 8 | W14: 8 | X14: 8 | Y14: 8 | Z14: 8 | AA14: 8 | AE14: 8 | AF14: 8 | AG14: 8 | AH14: 8 | AI14: 23 | AJ14: 184 | AK14: 23 | AL14: 184 | AM14: 8 | AN14: =COUNT(D14:R14) -> 11 | AO14: =SUM(D14:R14) -> 88
C15: Август | F15: 8 | G15: 8 | H15: 8 | I15: 8 | J15: 8 | M15: 8 | N15: 8 | O15: 8 | P15: 8 | Q15: 8 | T15: 8 | U15: 8 | V15: 8 | W15: 8 | X15: 8 | AA15: 8 | AB15: 8 | AC15: 8 | AD15: 8 | AE15: 8 | AH15: 8 | AI15: 21 | AJ15: 168 | AK15: 21 | AL15: 168 | AM15: 10 | AN15: =COUNT(D15:R15) -> 10 | AO15: =SUM(D15:R15) -> 80
C16: Сентябрь | D16: 8 | E16: 8 | F16: 8 | G16: 8 | J16: 8 | K16: 8 | L16: 8 | M16: 8 | N16: 8 | Q16: 7 | S16: 8 | T16: 8 | U16: 8 | X16: 8 | Y16: 8 | Z16: 8 | AA16: 8 | AB16: 8 | AE16: 8 | AF16: 8 | AG16: 8 | AH16: Х | AI16: 22 | AJ16: 176 | AK16: 22 | AL16: 176 | AM16: 8 | AN16: =COUNT(D16:R16) -> 10 | AO16: =SUM(D16:R16) -> 79
C17: 3 квартал | AI17: 66 | AJ17: 528 | AK17: 66 | AL17: 528 | AM17: 26 | AN17: =SUM(AN14:AN16) -> 31 | AO17: =SUM(AO14:AO16) -> 247
C18: Октябрь | D18: 8 | E18: 8 | H18: 8 | I18: 8 | J18: 8 | K18: 8 | L18: 8 | O18: 8 | P18: 8 | Q18: 8 | R18: 8 | S18: 8 | V18: 8 | W18: 8 | X18: 8 | Y18: 8 | Z18: 8 | AC18: 8 | AD18: 8 | AE18: 8 | AF18: 8 | AG18: 8 | AI18: 23 | AJ18: 184 | AK18: 23 | AL18: 184 | AM18: 8 | AN18: =COUNT(D18:R18) -> 11 | AO18: =SUM(D18:R18) -> 88
C19: Ноябрь | E19: 8 | F19: 7 | H19: 8 | I19: 8 | L19: 8 | M19: 8 | N19: 8 | O19: 8 | P19: 8 | S19: 8 | T19: 8 | U19: 8 | V19: 8 | W19: 8 | Z19: 8 | AA19: 8 | AB19: 8 | AC19: 8 | AD19: 8 | AG19: 8 | AH19: Х | AI19: 19 | AJ19: 151 | AK19: 19 | AL19: 151 | AM19: 11 | AN19: =COUNT(D19:R19) -> 9 | AO19: =SUM(D19:R19) -> 71
C20: Декабрь | D20: 8 | E20: 8 | F20: 8 | G20: 8 | J20: 8 | K20: 8 | L20: 8 | M20: 8 | N20: 8 | Q20: 8 | R20: 8 | S20: 8 | T20: 8 | U20: 8 | X20: 8 | Y20: 8 | Z20: 8 | AA20: 8 | AB20: 8 | AE20: 8 | AF20: 8 | AG20: 8 | AI20: 22 | AJ20: 176 | AK20: 22 | AL20: 176 | AM20: 9 | AN20: =COUNT(D20:R20) -> 11 | AO20: =SUM(D20:R20) -> 88
C21: 4 квартал | AI21: 64 | AJ21: 511 | AK21: 64 | AL21: 511 | AM21: 28 | AN21: =SUM(AN18:AN20) -> 31 | AO21: =SUM(AO18:AO20) -> 247
C22: Итого за год: | AI22: 246 | AJ22: 1963 | AK22: 246 | AL22: 1963 | AM22: 119 | AO22: =SUM(AO21,AO17,AO13,AO9) -> 916
AJ23: =AJ22/12 -> 163.58333 | AO23: =AO22/12 -> 76.333333
C28: шато | AN28: За первую половину месяца
C29: Месяц | D29: Часов за день ("Явка") | AI29: По графику | AK29: По производств. календарю | AN29: По графику
AK30: рабочих | AM30: не- раб. дней
D31: 1 | E31: 2 | F31: 3 | G31: 4 | H31: 5 | I31: 6 | J31: 7 | K31: 8 | L31: 9 | M31: 10 | N31: 11 | O31: 12 | P31: 13 | Q31: 14 | R31: 15 | S31: 16 | T31: 17 | U31: 18 | V31: 19 | W31: 20 | X31: 21 | Y31: 22 | Z31: 23 | AA31: 24 | AB31: 25 | AC31: 26 | AD31: 27 | AE31: 28 | AF31: 29 | AG31: 30 | AH31: 31 | AI31: дней | AJ31: часов | AK31: дней | AL31: часов | AN31: дней | AO31: часов
C32: Январь | O32: 7.2 | P32: 7.2 | Q32: 7.2 | R32: 7.2 | S32: 7.2 | V32: 7.2 | W32: 7.2 | X32: 7.2 | Y32: 7.2 | Z32: 7.2 | AC32: 7.2 | AD32: 7.2 | AE32: 7.2 | AF32: 7.2 | AG32: 7.2 | AI32: 17 | AJ32: 122.4 | AK32: 17 | AL32: 122.4 | AM32: 14 | AN32: =COUNT(D32:R32) -> 4 | AO32: =SUM(D32:R32) -> 28.8
C33: Февраль | E33: 7.2 | F33: 7.2 | G33: 7.2 | H33: 7.2 | I33: 7.2 | L33: 7.2 | M33: 7.2 | N33: 7.2 | O33: 7.2 | P33: 7.2 | S33: 7.2 | T33: 7.2 | U33: 7.2 | V33: 7.2 | W33: 7.2 | AA33: 7.2 | AB33: 7.2 | AC33: 7.2 | AD33: 7.2 | AF33: Х | AG33: Х | AH33: Х | AI33: 20 | AJ33: 144 | AK33: 20 | AL33: 144 | AM33: 8 | AN33: =COUNT(D33:R33) -> 10 | AO33: =SUM(D33:R33) -> 72
C34: Март | E34: 7.2 | F34: 7.2 | G34: 7.2 | H34: 7.2 | I34: 7.2 | M34: 7.2 | N34: 7.2 | O34: 7.2 | P34: 7.2 | S34: 7.2 | T34: 7.2 | U34: 7.2 | V34: 6.2 | Z34: 7.2 | AA34: 7.2 | AB34: 7.2 | AC34: 7.2 | AD34: 7.2 | AG34: 7.2 | AH34: 7.2 | AI34: 21 | AJ34: 150.2 | AK34: 21 | AL34: 150.2 | AM34: 10 | AN34: =COUNT(D34:R34) -> 9 | AO34: =SUM(D34:R34) -> 64.8
C35: 1 квартал | AI35: 58 | AJ35: 416.6 | AK35: 58 | AL35: 416.6 | AM35: 32 | AN35: =SUM(AN32:AN34) -> 23 | AO35: =SUM(AO32:AO34) -> 165.6
C36: Апрель | D36: 7.2 | E36: 7.2 | F36: 7.2 | I36: 7.2 | J36: 7.2 | K36: 7.2 | L36: 7.2 | M36: 7.2 | P36: 7.2 | Q36: 7.2 | R36: 7.2 | S36: 7.2 | T36: 7.2 | W36: 7.2 | X36: 7.2 | Y36: 7.2 | Z36: 7.2 | AA36: 7.2 | AD36: 7.2 | AE36: 6.2 | AG36: 6.2 | AH36: Х | AI36: 21 | AJ36: 149.2 | AK36: 21 | AL36: 149.2 | AM36: 9 | AN36: =COUNT(D36:R36) -> 11 | AO36: =SUM(D36:R36) -> 79.2
C37: Май | G37: 7.2 | H37: 7.2 | I37: 7.2 | J37: 7.2 | K37: 6.2 | O37: 7.2 | P37: 7.2 | Q37: 7.2 | R37: 7.2 | U37: 7.2 | V37: 7.2 | W37: 7.2 | X37: 7.2 | Y37: 7.2 | AB37: 7.2 | AC37: 6.2 | AE37: 7.2 | AF37: 7.2 | AI37: 18 | AJ37: 129.6 | AK37: 18 | AL37: 129.6 | AM37: 13 | AN37: =COUNT(D37:R37) -> 9 | AO37: =SUM(D37:R37) -> 63.8
C38: Июнь | D38: 7.2 | E38: 7.2 | F38: 7.2 | G38: 7.2 | H38: 7.2 | K38: 7.2 | L38: 7.2 | M38: 7.2 | N38: 6.2 | R38: 7.2 | S38: 7.2 | T38: 7.2 | U38: 7.2 | V38: 7.2 | Y38: 7.2 | Z38: 7.2 | AA38: 7.2 | AB38: 7.2 | AC38: 7.2 | AF38: 7.2 | AG38: 7.2 | AH38: Х | AI38: 19 | AJ38: 135.8 | AK38: 19 | AL38: 135.8 | AM38: 11 | AN38: =COUNT(D38:R38) -> 10 | AO38: =SUM(D38:R38) -> 71
C39: 2 квартал | AI39: 58 | AJ39: 414.6 | AK39: 58 | AL39: 414.6 | AM39: 33 | AN39: =SUM(AN36:AN38) -> 30 | AO39: =SUM(AO36:AO38) -> 214
C40: Июль | D40: 7.2 | E40: 7.2 | F40: 7.2 | I40: 7.2 | J40: 7.2 | K40: 7.2 | L40: 7.2 | M40: 7.2 | P40: 7.2 | Q40: 7.2 | R40: 7.2 | S40: 7.2 | T40: 7.2 | W40: 7.2 | X40: 7.2 | Y40: 7.2 | Z40: 7.2 | AA40: 7.2 | AE40: 7.2 | AF40: 7.2 | AG40: 7.2 | AH40: 7.2 | AI40: 23 | AJ40: 165.6 | AK40: 23 | AL40: 165.6 | AM40: 8 | AN40: =COUNT(D40:R40) -> 11 | AO40: =SUM(D40:R40) -> 79.2
C41: Август | F41: 7.2 | G41: 7.2 | H41: 7.2 | I41: 7.2 | J41: 7.2 | M41: 7.2 | N41: 7.2 | O41: 7.2 | P41: 7.2 | Q41: 7.2 | T41: 7.2 | U41: 7.2 | V41: 7.2 | W41: 7.2 | X41: 7.2 | AA41: 7.2 | AB41: 7.2 | AC41: 7.2 | AD41: 7.2 | AE41: 7.2 | AH41: 7.2 | AI41: 21 | AJ41: 151.2 | AK41: 21 | AL41: 151.2 | AM41: 10 | AN41: =COUNT(D41:R41) -> 10 | AO41: =SUM(D41:R41) -> 72
C42: Сентябрь | D42: 7.2 | E42: 7.2 | F42: 7.2 | G42: 7.2 | J42: 7.2 | K42: 7.2 | L42: 7.2 | M42: 7.2 | N42: 7.2 | Q42: 6.2 | S42: 7.2 | T42: 7.2 | U42: 7.2 | X42: 7.2 | Y42: 7.2 | Z42: 7.2 | AA42: 7.2 | AB42: 7.2 | AE42: 7.2 | AF42: 7.2 | AG42: 7.2 | AH42: Х | AI42: 22 | AJ42: 158.4 | AK42: 22 | AL42: 158.4 | AM42: 8 | AN42: =COUNT(D42:R42) -> 10 | AO42: =SUM(D42:R42) -> 71
C43: 3 квартал | AI43: 66 | AJ43: 475.2 | AK43: 66 | AL43: 475.2 | AM43: 26 | AN43: =SUM(AN40:AN42) -> 31 | AO43: =SUM(AO40:AO42) -> 222.2
C44: Октябрь | D44: 7.2 | E44: 7.2 | H44: 7.2 | I44: 7.2 | J44: 7.2 | K44: 7.2 | L44: 7.2 | O44: 7.2 | P44: 7.2 | Q44: 7.2 | R44: 7.2 | S44: 7.2 | V44: 7.2 | W44: 7.2 | X44: 7.2 | Y44: 7.2 | Z44: 7.2 | AC44: 7.2 | AD44: 7.2 | AE44: 7.2 | AF44: 7.2 | AG44: 7.2 | AI44: 23 | AJ44: 165.6 | AK44: 23 | AL44: 165.6 | AM44: 8 | AN44: =COUNT(D44:R44) -> 11 | AO44: =SUM(D44:R44) -> 79.2
C45: Ноябрь | E45: 7.2 | F45: 6.2 | H45: 7.2 | I45: 7.2 | L45: 7.2 | M45: 7.2 | N45: 7.2 | O45: 7.2 | P45: 7.2 | S45: 7.2 | T45: 7.2 | U45: 7.2 | V45: 7.2 | W45: 7.2 | Z45: 7.2 | AA45: 7.2 | AB45: 7.2 | AC45: 7.2 | AD45: 7.2 | AG45: 7.2 | AH45: Х | AI45: 19 | AJ45: 135.8 | AK45: 19 | AL45: 135.8 | AM45: 11 | AN45: =COUNT(D45:R45) -> 9 | AO45: =SUM(D45:R45) -> 63.8
...

Sheet ПК 2 Дагестан
B3: Количество дней и часов | C3: Календарные дни | D3: Рабочие дни | E3: Выходные и праздничные дни | F3: при 40-часовой рабочей неделе | G3: при 36-часовой рабочей неделе | H3: при 24-часовой рабочей неделе
B4: Январь | C4: 31 | D4: 15 | E4: 16 | F4: 120 | G4: 108 | H4: 72
B5: Февраль | C5: 28 | D5: 19 | E5: 9 | F5: 152 | G5: 136.8 | H5: 91.2
B6: Март | C6: 31 | D6: 20 | E6: 11 | F6: 159 | G6: 143 | H6: 95
B7: Апрель | C7: 30 | D7: 21 | E7: 9 | F7: 166 | G7: 149.2 | H7: 94
B8: Май | C8: 31 | D8: 18 | E8: 13 | F8: 142 | G8: 127.6 | H8: 86.4
B9: Июнь | C9: 30 | D9: 21 | E9: 9 | F9: 167 | G9: 150.2 | H9: 84.4
B10: Июль | C10: 31 | D10: 22 | E10: 9 | F10: 176 | G10: 158.4 | H10: 104.6
B11: Август | C11: 31 | D11: 21 | E11: 10 | F11: 168 | G11: 151.2 | H11: 100.8
B12: Сентябрь | C12: 30 | D12: 21 | E12: 9 | F12: 167 | G12: 150.2 | H12: 100.8
B13: Октябрь | C13: 31 | D13: 22 | E13: 9 | F13: 176 | G13: 158.4 | H13: 110.4
B14: Ноябрь | C14: 30 | D14: 20 | E14: 10 | F14: 159 | G14: 143 | H14: 90.2
B15: Декабрь | C15: 31 | D15: 22 | E15: 9 | F15: 176 | G15: 158.4 | H15: 105.6
B17: 1 кв | F17: =SUM(F4:F6) -> 431 | G17: =SUM(G4:G6) -> 387.8
B18: 2 кв | F18: =SUM(F7:F9) -> 475 | G18: =SUM(G7:G9) -> 427
B19: 3 кв | F19: =SUM(F10:F12) -> 511 | G19: =SUM(G10:G12) -> 459.8
B20: 4 кв | F20: =SUM(F13:F15) -> 511 | G20: =SUM(G13:G15) -> 459.8
F21: =SUM(F17:F20) -> 1928 | G21: =SUM(G17:G20) -> 1734.4
F22: =F21/12 -> 160.66667 | G22: =G21/12 -> 144.53333

Sheet Справочный лист
B3: Явка | C3: Я | D3: 8 | F3: Январь | H3: ООО «АЛВИСА», филиал ШАТО АЛВИСА (CHÂTEAU ALVISA) | J3: 1 | K3: ПН | M3: 1 | N3: 2 | O3: 3 | P3: 4 | Q3: 5 | R3: 6 | S3: 7 | T3: 8 | U3: 9 | V3: 10 | W3: 11 | X3: 12 | Y3: 13 | Z3: 14 | AA3: 15 | AB3: 16 | AC3: 17 | AD3: 18 | AE3: 19 | AF3: 20 | AG3: 21 | AH3: 22 | AI3: 23 | AJ3: 24 | AK3: 25 | AL3: 26 | AM3: 27 | AN3: 28 | AO3: 29 | AP3: 30 | AQ3: 31
B4: Явка в дневную смену | C4: Д | D4: 11 | F4: Февраль | H4: ООО "АЛВИСА", ФИЛИАЛ АЛВИСА ВИСКИ ДИСТИЛЛЕРИ (ALVISA WHISKY DISTILLERY) | J4: 2 | K4: ВТ | M4: 26
B5: Явка в ночную смену | C5: Н | D5: 11 | F5: Март | H5: ООО "АЛВИСА", филиал АЛВИСА ВИСКИ (ALVISA WHISKY) | J5: 3 | K5: СР
B6: Отпуска ежегодн.оплачиваемые или без сохранения ЗП | C6: ОТ | F6: Апрель | H6: ООО "АЛВИСА", филиал ЗАВОД АЛВИСА БЭВЭРИДЖ (ALVISA BEVERAGE) | J6: 4 | K6: ЧТ | M6: Январь | N6: 1
B7: Дни до трудоустройства или после увольнения | C7: Х | F7: Май | H7: ООО «АЛВИСА», филиал ЗАВОД АЛВИСА БЭВЭРИДЖ | J7: 5 | K7: ПТ | M7: Февраль | N7: 2
B8: Оформленный БЛ | C8: Б | F8: Июнь | H8: ООО «АЛВИСА», ФИЛИАЛ АЛВИСА ДИСТИЛЛЕРИ (ALVISA DISTILLERY) | J8: 6 | K8: СБ | M8: Март | N8: 3
B9: Отпуск без сохранения | C9: ДО | F9: Июль | J9: 7 | K9: ВС | M9: Апрель | N9: 4
B10: Приостановление трудового договора | C10: ПТД | F10: Август | H10: Мужской | M10: Май | N10: 5
B11: Дополнительные выходные дни (оплачиваемые) | C11: ОВ | F11: Сентябрь | H11: Женский | M11: Июнь | N11: 6
B12: Беременность и роды | C12: Р | F12: Октябрь | M12: Июль | N12: 7
B13: Декретный отпуск | C13: ОЖ | F13: Ноябрь | M13: Август | N13: 8
F14: Декабрь | M14: Сентябрь | N14: 9
M15: Октябрь | N15: 10
M16: Ноябрь | N16: 11
M17: Декабрь | N17: 12
